[I 22:29:01.806 NotebookApp] [nb_conda_kernels] enabled, 9 kernels found
[I 22:29:02.450 NotebookApp] Authentication of /metrics is OFF, since other authentication is disabled.
[W 22:29:05.630 NotebookApp] All authentication is disabled.  Anyone who can connect to this server will be able to run code.
[W 2023-01-28 22:29:15.124 LabApp] Config option `kernel_spec_manager_class` not recognized by `LabApp`.
[W 2023-01-28 22:29:15.154 LabApp] 'ip' has moved from NotebookApp to ServerApp. This config will be passed to ServerApp. Be sure to update your config before our next release.
[W 2023-01-28 22:29:15.154 LabApp] 'port' has moved from NotebookApp to ServerApp. This config will be passed to ServerApp. Be sure to update your config before our next release.
[W 2023-01-28 22:29:15.159 LabApp] 'token' has moved from NotebookApp to ServerApp. This config will be passed to ServerApp. Be sure to update your config before our next release.
[W 2023-01-28 22:29:15.159 LabApp] 'password' has moved from NotebookApp to ServerApp. This config will be passed to ServerApp. Be sure to update your config before our next release.
[W 2023-01-28 22:29:15.159 LabApp] 'password' has moved from NotebookApp to ServerApp. This config will be passed to ServerApp. Be sure to update your config before our next release.
[W 2023-01-28 22:29:15.159 LabApp] 'password' has moved from NotebookApp to ServerApp. This config will be passed to ServerApp. Be sure to update your config before our next release.
[W 2023-01-28 22:29:15.161 LabApp] Config option `kernel_spec_manager_class` not recognized by `LabApp`.
[W 2023-01-28 22:29:15.188 LabApp] Config option `kernel_spec_manager_class` not recognized by `LabApp`.
[I 2023-01-28 22:29:15.229 LabApp] JupyterLab extension loaded from /om/user/leokoz8/envs/boa_rnn/lib/python3.8/site-packages/jupyterlab
[I 2023-01-28 22:29:15.229 LabApp] JupyterLab application directory is /om/user/leokoz8/envs/boa_rnn/share/jupyter/lab
[I 22:29:15.248 NotebookApp] Serving notebooks from local directory: /rdma/vast-rdma/vast/fiete/leokoz8/code/boa_rnn
[I 22:29:15.249 NotebookApp] Jupyter Notebook 6.3.0 is running at:
[I 22:29:15.249 NotebookApp] http://node055.cm.cluster:9000/
[I 22:29:15.249 NotebookApp] Use Control-C to stop this server and shut down all kernels (twice to skip confirmation).
[W 22:29:43.824 NotebookApp] 404 GET /hub/api (172.16.20.254) 315.100000ms referer=None
[W 22:32:08.788 NotebookApp] 403 POST /api/contents?1674963128780 (172.16.20.254): '_xsrf' argument missing from POST
[W 22:32:08.823 NotebookApp] '_xsrf' argument missing from POST
[W 22:32:08.824 NotebookApp] 403 POST /api/contents?1674963128780 (172.16.20.254) 38.690000ms referer=None
[W 22:32:08.843 NotebookApp] 403 POST /api/sessions?1674963128826 (172.16.20.254): '_xsrf' argument missing from POST
[W 22:32:08.844 NotebookApp] '_xsrf' argument missing from POST
[W 22:32:08.844 NotebookApp] 403 POST /api/sessions?1674963128826 (172.16.20.254) 1.500000ms referer=None
[I 22:34:18.620 NotebookApp] 302 GET / (172.16.24.254) 11.000000ms
/om/user/leokoz8/envs/boa_rnn/lib/python3.8/json/encoder.py:257: UserWarning: date_default is deprecated since jupyter_client 7.0.0. Use jupyter_client.jsonutil.json_default.
  return _iterencode(o, 0)
[W 22:35:00.798 NotebookApp] Notebook notebooks/test_nb.ipynb is not trusted
Exception in callback <TaskWakeupMethWrapper object at 0x2accea6368b0>(<Future finis...late\r\n\r\n'>)
handle: <Handle <TaskWakeupMethWrapper object at 0x2accea6368b0>(<Future finis...late\r\n\r\n'>)>
Traceback (most recent call last):
  File "/om/user/leokoz8/envs/boa_rnn/lib/python3.8/asyncio/events.py", line 81, in _run
    self._context.run(self._callback, *self._args)
RuntimeError: Cannot enter into task <Task pending name='Task-163' coro=<HTTP1ServerConnection._server_request_loop() running at /om/user/leokoz8/envs/boa_rnn/lib/python3.8/site-packages/tornado/http1connection.py:825> wait_for=<Future finished result=b'GET /api/co...flate\r\n\r\n'> cb=[IOLoop.add_future.<locals>.<lambda>() at /om/user/leokoz8/envs/boa_rnn/lib/python3.8/site-packages/tornado/ioloop.py:687]> while another task <Task pending name='Task-2' coro=<KernelManager._async_start_kernel() running at /om/user/leokoz8/envs/boa_rnn/lib/python3.8/site-packages/jupyter_client/manager.py:71>> is being executed.
Exception in callback <TaskWakeupMethWrapper object at 0x2accea6265b0>(<Future finis...late\r\n\r\n'>)
handle: <Handle <TaskWakeupMethWrapper object at 0x2accea6265b0>(<Future finis...late\r\n\r\n'>)>
Traceback (most recent call last):
  File "/om/user/leokoz8/envs/boa_rnn/lib/python3.8/asyncio/events.py", line 81, in _run
    self._context.run(self._callback, *self._args)
RuntimeError: Cannot enter into task <Task pending name='Task-165' coro=<HTTP1ServerConnection._server_request_loop() running at /om/user/leokoz8/envs/boa_rnn/lib/python3.8/site-packages/tornado/http1connection.py:825> wait_for=<Future finished result=b'GET /kernel...flate\r\n\r\n'> cb=[IOLoop.add_future.<locals>.<lambda>() at /om/user/leokoz8/envs/boa_rnn/lib/python3.8/site-packages/tornado/ioloop.py:687]> while another task <Task pending name='Task-2' coro=<KernelManager._async_start_kernel() running at /om/user/leokoz8/envs/boa_rnn/lib/python3.8/site-packages/jupyter_client/manager.py:71>> is being executed.
[I 22:35:01.368 NotebookApp] Kernel started: cad4f5b6-759c-49a2-a905-a57d0292dcfa, name: python3
/om/user/leokoz8/envs/boa_rnn/lib/python3.8/json/encoder.py:257: UserWarning: date_default is deprecated since jupyter_client 7.0.0. Use jupyter_client.jsonutil.json_default.
  return _iterencode(o, 0)
[I 22:36:36.443 NotebookApp] Kernel interrupted: cad4f5b6-759c-49a2-a905-a57d0292dcfa
[I 22:36:39.790 NotebookApp] Saving file at /notebooks/test_nb.ipynb
[W 22:36:39.792 NotebookApp] Notebook notebooks/test_nb.ipynb is not trusted
[I 22:36:43.202 NotebookApp] Starting buffering for cad4f5b6-759c-49a2-a905-a57d0292dcfa:8156c3bf00c541b386649551a4394095
[I 22:36:43.258 NotebookApp] Kernel shutdown: cad4f5b6-759c-49a2-a905-a57d0292dcfa
[W 22:37:09.505 NotebookApp] Notebook notebooks/test_nb.ipynb is not trusted
Exception in callback <TaskWakeupMethWrapper object at 0x2accea889940>(<Future finished result=None>)
handle: <Handle <TaskWakeupMethWrapper object at 0x2accea889940>(<Future finished result=None>)>
Traceback (most recent call last):
  File "/om/user/leokoz8/envs/boa_rnn/lib/python3.8/asyncio/events.py", line 81, in _run
    self._context.run(self._callback, *self._args)
RuntimeError: Cannot enter into task <Task pending name='Task-166' coro=<HTTP1ServerConnection._server_request_loop() running at /om/user/leokoz8/envs/boa_rnn/lib/python3.8/site-packages/tornado/http1connection.py:825> wait_for=<Future finished result=None> cb=[IOLoop.add_future.<locals>.<lambda>() at /om/user/leokoz8/envs/boa_rnn/lib/python3.8/site-packages/tornado/ioloop.py:687]> while another task <Task pending name='Task-162' coro=<MappingKernelManager.start_kernel() running at /om/user/leokoz8/envs/boa_rnn/lib/python3.8/site-packages/notebook/services/kernels/kernelmanager.py:176> cb=[IOLoop.add_future.<locals>.<lambda>() at /om/user/leokoz8/envs/boa_rnn/lib/python3.8/site-packages/tornado/ioloop.py:694]> is being executed.
Exception in callback <TaskWakeupMethWrapper object at 0x2acceae4dd60>(<Future finis...late\r\n\r\n'>)
handle: <Handle <TaskWakeupMethWrapper object at 0x2acceae4dd60>(<Future finis...late\r\n\r\n'>)>
Traceback (most recent call last):
  File "/om/user/leokoz8/envs/boa_rnn/lib/python3.8/asyncio/events.py", line 81, in _run
    self._context.run(self._callback, *self._args)
RuntimeError: Cannot enter into task <Task pending name='Task-164' coro=<HTTP1ServerConnection._server_request_loop() running at /om/user/leokoz8/envs/boa_rnn/lib/python3.8/site-packages/tornado/http1connection.py:825> wait_for=<Future finished result=b'GET /static...flate\r\n\r\n'> cb=[IOLoop.add_future.<locals>.<lambda>() at /om/user/leokoz8/envs/boa_rnn/lib/python3.8/site-packages/tornado/ioloop.py:687]> while another task <Task pending name='Task-164' coro=<KernelManager._async_start_kernel() running at /om/user/leokoz8/envs/boa_rnn/lib/python3.8/site-packages/jupyter_client/manager.py:71>> is being executed.
Exception in callback <TaskWakeupMethWrapper object at 0x2acceac89fa0>(<Future finis...late\r\n\r\n'>)
handle: <Handle <TaskWakeupMethWrapper object at 0x2acceac89fa0>(<Future finis...late\r\n\r\n'>)>
Traceback (most recent call last):
  File "/om/user/leokoz8/envs/boa_rnn/lib/python3.8/asyncio/events.py", line 81, in _run
    self._context.run(self._callback, *self._args)
RuntimeError: Cannot enter into task <Task pending name='Task-159' coro=<HTTP1ServerConnection._server_request_loop() running at /om/user/leokoz8/envs/boa_rnn/lib/python3.8/site-packages/tornado/http1connection.py:825> wait_for=<Future finished result=b'GET /kernel...flate\r\n\r\n'> cb=[IOLoop.add_future.<locals>.<lambda>() at /om/user/leokoz8/envs/boa_rnn/lib/python3.8/site-packages/tornado/ioloop.py:687]> while another task <Task pending name='Task-163' coro=<MultiKernelManager._async_start_kernel() running at /om/user/leokoz8/envs/boa_rnn/lib/python3.8/site-packages/jupyter_client/multikernelmanager.py:207>> is being executed.
[I 22:37:10.072 NotebookApp] Kernel started: d9cc07f4-811a-4248-be53-f385fb39b261, name: python3
[I 22:39:10.514 NotebookApp] Saving file at /notebooks/test_nb.ipynb
[W 22:39:10.522 NotebookApp] Notebook notebooks/test_nb.ipynb is not trusted
[I 22:39:29.985 NotebookApp] Starting buffering for d9cc07f4-811a-4248-be53-f385fb39b261:ef5c738bf1eb45d6908f192886a00ec5
slurmstepd: error: *** JOB 29159877 ON node055 CANCELLED AT 2023-01-28T22:39:42 ***
