[I 22:43:48.134 NotebookApp] [nb_conda_kernels] enabled, 9 kernels found
[I 22:43:48.423 NotebookApp] Authentication of /metrics is OFF, since other authentication is disabled.
[W 22:43:50.561 NotebookApp] All authentication is disabled.  Anyone who can connect to this server will be able to run code.
[W 2023-01-28 22:43:53.818 LabApp] Config option `kernel_spec_manager_class` not recognized by `LabApp`.
[W 2023-01-28 22:43:53.824 LabApp] 'ip' has moved from NotebookApp to ServerApp. This config will be passed to ServerApp. Be sure to update your config before our next release.
[W 2023-01-28 22:43:53.824 LabApp] 'port' has moved from NotebookApp to ServerApp. This config will be passed to ServerApp. Be sure to update your config before our next release.
[W 2023-01-28 22:43:53.824 LabApp] 'token' has moved from NotebookApp to ServerApp. This config will be passed to ServerApp. Be sure to update your config before our next release.
[W 2023-01-28 22:43:53.824 LabApp] 'password' has moved from NotebookApp to ServerApp. This config will be passed to ServerApp. Be sure to update your config before our next release.
[W 2023-01-28 22:43:53.824 LabApp] 'password' has moved from NotebookApp to ServerApp. This config will be passed to ServerApp. Be sure to update your config before our next release.
[W 2023-01-28 22:43:53.824 LabApp] 'password' has moved from NotebookApp to ServerApp. This config will be passed to ServerApp. Be sure to update your config before our next release.
[W 2023-01-28 22:43:53.825 LabApp] Config option `kernel_spec_manager_class` not recognized by `LabApp`.
[W 2023-01-28 22:43:53.834 LabApp] Config option `kernel_spec_manager_class` not recognized by `LabApp`.
[I 2023-01-28 22:43:53.835 LabApp] JupyterLab extension loaded from /om/user/leokoz8/envs/boa_rnn/lib/python3.8/site-packages/jupyterlab
[I 2023-01-28 22:43:53.835 LabApp] JupyterLab application directory is /om/user/leokoz8/envs/boa_rnn/share/jupyter/lab
[I 22:43:53.842 NotebookApp] Serving notebooks from local directory: /rdma/vast-rdma/vast/fiete/leokoz8/code/boa_rnn
[I 22:43:53.842 NotebookApp] Jupyter Notebook 6.3.0 is running at:
[I 22:43:53.842 NotebookApp] http://node076:9000/
[I 22:43:53.842 NotebookApp] Use Control-C to stop this server and shut down all kernels (twice to skip confirmation).
[I 22:45:29.967 NotebookApp] 302 GET / (172.16.24.254) 0.940000ms
/om/user/leokoz8/envs/boa_rnn/lib/python3.8/json/encoder.py:257: UserWarning: date_default is deprecated since jupyter_client 7.0.0. Use jupyter_client.jsonutil.json_default.
  return _iterencode(o, 0)
[W 22:45:40.398 NotebookApp] Notebook notebooks/test_nb.ipynb is not trusted
Exception in callback <TaskWakeupMethWrapper object at 0x2ab43bc58760>(<Future finished result=None>)
handle: <Handle <TaskWakeupMethWrapper object at 0x2ab43bc58760>(<Future finished result=None>)>
Traceback (most recent call last):
  File "/om/user/leokoz8/envs/boa_rnn/lib/python3.8/asyncio/events.py", line 81, in _run
    self._context.run(self._callback, *self._args)
RuntimeError: Cannot enter into task <Task pending name='Task-11' coro=<HTTP1ServerConnection._server_request_loop() running at /om/user/leokoz8/envs/boa_rnn/lib/python3.8/site-packages/tornado/http1connection.py:825> wait_for=<Future finished result=None> cb=[IOLoop.add_future.<locals>.<lambda>() at /om/user/leokoz8/envs/boa_rnn/lib/python3.8/site-packages/tornado/ioloop.py:687]> while another task <Task pending name='Task-35' coro=<MappingKernelManager.start_kernel() running at /om/user/leokoz8/envs/boa_rnn/lib/python3.8/site-packages/notebook/services/kernels/kernelmanager.py:176> cb=[IOLoop.add_future.<locals>.<lambda>() at /om/user/leokoz8/envs/boa_rnn/lib/python3.8/site-packages/tornado/ioloop.py:687]> is being executed.
Exception in callback <TaskWakeupMethWrapper object at 0x2ab42dd80f70>(<Future finis...late\r\n\r\n'>)
handle: <Handle <TaskWakeupMethWrapper object at 0x2ab42dd80f70>(<Future finis...late\r\n\r\n'>)>
Traceback (most recent call last):
  File "/om/user/leokoz8/envs/boa_rnn/lib/python3.8/asyncio/events.py", line 81, in _run
    self._context.run(self._callback, *self._args)
RuntimeError: Cannot enter into task <Task pending name='Task-12' coro=<HTTP1ServerConnection._server_request_loop() running at /om/user/leokoz8/envs/boa_rnn/lib/python3.8/site-packages/tornado/http1connection.py:825> wait_for=<Future finished result=b'GET /kernel...flate\r\n\r\n'> cb=[IOLoop.add_future.<locals>.<lambda>() at /om/user/leokoz8/envs/boa_rnn/lib/python3.8/site-packages/tornado/ioloop.py:687]> while another task <Task pending name='Task-2' coro=<KernelManager._async_start_kernel() running at /om/user/leokoz8/envs/boa_rnn/lib/python3.8/site-packages/jupyter_client/manager.py:71>> is being executed.
Exception in callback <TaskWakeupMethWrapper object at 0x2ab43bc58be0>(<Future finis...late\r\n\r\n'>)
handle: <Handle <TaskWakeupMethWrapper object at 0x2ab43bc58be0>(<Future finis...late\r\n\r\n'>)>
Traceback (most recent call last):
  File "/om/user/leokoz8/envs/boa_rnn/lib/python3.8/asyncio/events.py", line 81, in _run
    self._context.run(self._callback, *self._args)
RuntimeError: Cannot enter into task <Task pending name='Task-4' coro=<HTTP1ServerConnection._server_request_loop() running at /om/user/leokoz8/envs/boa_rnn/lib/python3.8/site-packages/tornado/http1connection.py:825> wait_for=<Future finished result=b'GET /static...flate\r\n\r\n'> cb=[IOLoop.add_future.<locals>.<lambda>() at /om/user/leokoz8/envs/boa_rnn/lib/python3.8/site-packages/tornado/ioloop.py:687]> while another task <Task pending name='Task-2' coro=<KernelManager._async_start_kernel() running at /om/user/leokoz8/envs/boa_rnn/lib/python3.8/site-packages/jupyter_client/manager.py:71>> is being executed.
Exception in callback <TaskWakeupMethWrapper object at 0x2ab43bc586a0>(<Future finis...late\r\n\r\n'>)
handle: <Handle <TaskWakeupMethWrapper object at 0x2ab43bc586a0>(<Future finis...late\r\n\r\n'>)>
Traceback (most recent call last):
  File "/om/user/leokoz8/envs/boa_rnn/lib/python3.8/asyncio/events.py", line 81, in _run
    self._context.run(self._callback, *self._args)
RuntimeError: Cannot enter into task <Task pending name='Task-10' coro=<HTTP1ServerConnection._server_request_loop() running at /om/user/leokoz8/envs/boa_rnn/lib/python3.8/site-packages/tornado/http1connection.py:825> wait_for=<Future finished result=b'GET /static...flate\r\n\r\n'> cb=[IOLoop.add_future.<locals>.<lambda>() at /om/user/leokoz8/envs/boa_rnn/lib/python3.8/site-packages/tornado/ioloop.py:687]> while another task <Task pending name='Task-2' coro=<KernelManager._async_start_kernel() running at /om/user/leokoz8/envs/boa_rnn/lib/python3.8/site-packages/jupyter_client/manager.py:71>> is being executed.
Exception in callback <TaskWakeupMethWrapper object at 0x2ab43bc02220>(<Future finis...late\r\n\r\n'>)
handle: <Handle <TaskWakeupMethWrapper object at 0x2ab43bc02220>(<Future finis...late\r\n\r\n'>)>
Traceback (most recent call last):
  File "/om/user/leokoz8/envs/boa_rnn/lib/python3.8/asyncio/events.py", line 81, in _run
    self._context.run(self._callback, *self._args)
RuntimeError: Cannot enter into task <Task pending name='Task-13' coro=<HTTP1ServerConnection._server_request_loop() running at /om/user/leokoz8/envs/boa_rnn/lib/python3.8/site-packages/tornado/http1connection.py:825> wait_for=<Future finished result=b'GET /static...flate\r\n\r\n'> cb=[IOLoop.add_future.<locals>.<lambda>() at /om/user/leokoz8/envs/boa_rnn/lib/python3.8/site-packages/tornado/ioloop.py:687]> while another task <Task pending name='Task-2' coro=<KernelManager._async_start_kernel() running at /om/user/leokoz8/envs/boa_rnn/lib/python3.8/site-packages/jupyter_client/manager.py:71>> is being executed.
[I 22:45:40.779 NotebookApp] Kernel started: 2e0e6165-d3e0-4616-b521-e16fd274b12e, name: python3
/om/user/leokoz8/envs/boa_rnn/lib/python3.8/json/encoder.py:257: UserWarning: date_default is deprecated since jupyter_client 7.0.0. Use jupyter_client.jsonutil.json_default.
  return _iterencode(o, 0)
[I 22:46:14.818 NotebookApp] Starting buffering for 2e0e6165-d3e0-4616-b521-e16fd274b12e:c34908918d4444b09c101ec5ae178b5e
[W 22:46:19.235 NotebookApp] Notebook notebooks/test_nb.ipynb is not trusted
[I 22:46:29.545 NotebookApp] Starting buffering for 2e0e6165-d3e0-4616-b521-e16fd274b12e:69b3ef20272a44ef9ef4859987918fd1
[W 22:46:53.623 NotebookApp] 404 GET /hub/api (172.16.24.254) 33.500000ms referer=None
[W 22:46:59.366 NotebookApp] Notebook notebooks/test_nb.ipynb is not trusted
[I 22:47:05.026 NotebookApp] Starting buffering for 2e0e6165-d3e0-4616-b521-e16fd274b12e:adfcfc78b21a45fba5357d94d2b1473c
[I 22:47:05.036 NotebookApp] Kernel shutdown: 2e0e6165-d3e0-4616-b521-e16fd274b12e
[W 22:47:13.631 NotebookApp] 403 POST /api/contents?1674964033626 (172.16.24.254): '_xsrf' argument missing from POST
[W 22:47:13.633 NotebookApp] '_xsrf' argument missing from POST
[W 22:47:13.633 NotebookApp] 403 POST /api/contents?1674964033626 (172.16.24.254) 2.390000ms referer=None
[W 22:47:13.643 NotebookApp] 403 POST /api/sessions?1674964033635 (172.16.24.254): '_xsrf' argument missing from POST
[W 22:47:13.643 NotebookApp] '_xsrf' argument missing from POST
[W 22:47:13.643 NotebookApp] 403 POST /api/sessions?1674964033635 (172.16.24.254) 1.170000ms referer=None
[W 22:48:52.341 NotebookApp] Notebook notebooks/test_nb.ipynb is not trusted
[I 22:48:52.728 NotebookApp] Kernel started: 5ccb6a16-dbe2-40cc-b1be-70062348d559, name: python3
[I 22:50:52.804 NotebookApp] Saving file at /notebooks/test_nb.ipynb
[W 22:50:52.806 NotebookApp] Notebook notebooks/test_nb.ipynb is not trusted
[I 22:52:52.859 NotebookApp] Saving file at /notebooks/test_nb.ipynb
[W 22:52:52.861 NotebookApp] Notebook notebooks/test_nb.ipynb is not trusted
[I 22:56:52.841 NotebookApp] Saving file at /notebooks/test_nb.ipynb
[W 22:56:52.843 NotebookApp] Notebook notebooks/test_nb.ipynb is not trusted
[I 22:58:52.826 NotebookApp] Saving file at /notebooks/test_nb.ipynb
[I 23:00:52.808 NotebookApp] Saving file at /notebooks/test_nb.ipynb
[I 23:02:02.204 NotebookApp] Saving file at /notebooks/test_nb.ipynb
[I 23:02:03.178 NotebookApp] Starting buffering for 5ccb6a16-dbe2-40cc-b1be-70062348d559:7d2e5794bee34e19819c20178019a359
slurmstepd: error: *** JOB 29159981 ON node076 CANCELLED AT 2023-01-28T23:02:21 ***
